事件处理过程中抛出的错误，可以使用try...catch捕获。

<pre>
    var EventEmitter = require('events').EventEmitter;
    var emitter = new EventEmitter();

    emitter.on('beep', function () {
    console.log('beep');
    });

    emitter.on('beep', function () {
    throw Error('oops!');
    });

    emitter.on('beep', function () {
    console.log('beep again');
    });

    console.log('before emit');

    try {
    emitter.emit('beep');
    } catch(err) {
    console.error('caught while emitting:', err.message);
    }

    console.log('after emit');
</pre>

可以看到，第二个监听函数抛出的错误被try...catch代码块捕获了。一旦被捕获，该事件后面的监听函数都不会再执行了。